ERROR:root:Exception occured
Traceback (most recent call last):
  File "D:/ViteosModel2.0/249_Production_Model.py", line 1138, in <module>
    print(meo.shape[0])
NameError: name 'meo' is not defined
