ERROR:root:Exception occured
Traceback (most recent call last):
  File "D:\ViteosModel2.0\455_Production_Model.py", line 1397, in <module>
    data2 = df3[col_sel]
  File "C:\ProgramData\Anaconda3\lib\site-packages\pandas\core\frame.py", line 2986, in __getitem__
    indexer = self.loc._convert_to_indexer(key, axis=1, raise_missing=True)
  File "C:\ProgramData\Anaconda3\lib\site-packages\pandas\core\indexing.py", line 1285, in _convert_to_indexer
    return self._get_listlike_indexer(obj, axis, **kwargs)[1]
  File "C:\ProgramData\Anaconda3\lib\site-packages\pandas\core\indexing.py", line 1092, in _get_listlike_indexer
    keyarr, indexer, o._get_axis_number(axis), raise_missing=raise_missing
  File "C:\ProgramData\Anaconda3\lib\site-packages\pandas\core\indexing.py", line 1185, in _validate_read_indexer
    raise KeyError("{} not in index".format(not_found))
KeyError: "['Category'] not in index"
