ERROR:root:Exception occured
Traceback (most recent call last):
  File "C:\ProgramData\Anaconda3\lib\site-packages\pandas\core\indexes\base.py", line 2897, in get_loc
    return self._engine.get_loc(key)
  File "pandas\_libs\index.pyx", line 107, in pandas._libs.index.IndexEngine.get_loc
  File "pandas\_libs\index.pyx", line 131, in pandas._libs.index.IndexEngine.get_loc
  File "pandas\_libs\hashtable_class_helper.pxi", line 1607, in pandas._libs.hashtable.PyObjectHashTable.get_item
  File "pandas\_libs\hashtable_class_helper.pxi", line 1614, in pandas._libs.hashtable.PyObjectHashTable.get_item
KeyError: 'Date'

During handling of the above exception, another exception occurred:

Traceback (most recent call last):
  File "D:\ViteosModel2.0\455_Production_Model.py", line 1019, in <module>
    meo_df['Date'] = pd.to_datetime(meo_df['Date']).dt.date
  File "C:\ProgramData\Anaconda3\lib\site-packages\pandas\core\frame.py", line 2980, in __getitem__
    indexer = self.columns.get_loc(key)
  File "C:\ProgramData\Anaconda3\lib\site-packages\pandas\core\indexes\base.py", line 2899, in get_loc
    return self._engine.get_loc(self._maybe_cast_indexer(key))
  File "pandas\_libs\index.pyx", line 107, in pandas._libs.index.IndexEngine.get_loc
  File "pandas\_libs\index.pyx", line 131, in pandas._libs.index.IndexEngine.get_loc
  File "pandas\_libs\hashtable_class_helper.pxi", line 1607, in pandas._libs.hashtable.PyObjectHashTable.get_item
  File "pandas\_libs\hashtable_class_helper.pxi", line 1614, in pandas._libs.hashtable.PyObjectHashTable.get_item
KeyError: 'Date'
