ERROR:root:Exception occured
Traceback (most recent call last):
  File "D:/ViteosModel2.0/897_Production_Model.py", line 414, in <module>
    param_start_col_num = Schonfeld_897_position_file_first_sheet_origin_col_number)
  File "D:/ViteosModel2.0/897_Production_Model.py", line 115, in read_passowrd_protected_pos_file_and_concat_to_single_pos_df
    content = xl_sh.Range(xl_sh.Cells(param_start_row_num, param_start_col_num), xl_sh.Cells(last_row, last_col)).Value
  File "C:\ProgramData\Anaconda3\lib\site-packages\win32com\client\dynamic.py", line 197, in __call__
    return self._get_good_object_(self._oleobj_.Invoke(*allArgs),self._olerepr_.defaultDispatchName,None)
pywintypes.com_error: (-2147352567, 'Exception occurred.', (0, None, None, None, 0, -2146827284), None)
