ERROR:root:Exception occured
Traceback (most recent call last):
  File "C:\ProgramData\Anaconda3\lib\site-packages\win32com\client\dynamic.py", line 89, in _GetGoodDispatch
    IDispatch = pythoncom.connect(IDispatch)
pywintypes.com_error: (-2147221021, 'Operation unavailable', None, None)

During handling of the above exception, another exception occurred:

Traceback (most recent call last):
  File "D:\ViteosModel2.0\897_Production_Model.py", line 466, in <module>
    param_pos_without_password_filepath=filename_pos_file)
  File "D:\ViteosModel2.0\897_Production_Model.py", line 51, in remove_password_xlsx
    xcl = win32com.client.Dispatch("Excel.Application")
  File "C:\ProgramData\Anaconda3\lib\site-packages\win32com\client\__init__.py", line 95, in Dispatch
    dispatch, userName = dynamic._GetGoodDispatchAndUserName(dispatch,userName,clsctx)
  File "C:\ProgramData\Anaconda3\lib\site-packages\win32com\client\dynamic.py", line 114, in _GetGoodDispatchAndUserName
    return (_GetGoodDispatch(IDispatch, clsctx), userName)
  File "C:\ProgramData\Anaconda3\lib\site-packages\win32com\client\dynamic.py", line 91, in _GetGoodDispatch
    IDispatch = pythoncom.CoCreateInstance(IDispatch, None, clsctx, pythoncom.IID_IDispatch)
pywintypes.com_error: (-2147024891, 'Access is denied.', None, None)
