ERROR:root:Exception occured
Traceback (most recent call last):
  File "D:/ViteosModel2.0/897_Production_Model.py", line 433, in <module>
    param_pos_cols_list = Schonfeld_897_position_file_columns_list)
  File "D:/ViteosModel2.0/897_Production_Model.py", line 104, in read_passowrd_protected_pos_file_and_concat_to_single_pos_df
    cell_val = xl_sh.Cells(row_num, param_start_col_num).Value
  File "C:\ProgramData\Anaconda3\lib\site-packages\win32com\client\__init__.py", line 474, in __getattr__
    return self._ApplyTypes_(*args)
  File "C:\ProgramData\Anaconda3\lib\site-packages\win32com\client\__init__.py", line 467, in _ApplyTypes_
    self._oleobj_.InvokeTypes(dispid, 0, wFlags, retType, argTypes, *args),
pywintypes.com_error: (-2147418111, 'Call was rejected by callee.', None, None)
