ERROR:root:Exception occured
Traceback (most recent call last):
  File "D:\ViteosModel2.0\379_Production_Model.py", line 4655, in <module>
    final_mto_table_copy['BreakID_Side1'] = final_mto_table_copy['BreakID_Side1'].astype(int)
  File "C:\ProgramData\Anaconda3\lib\site-packages\pandas\core\generic.py", line 5882, in astype
    dtype=dtype, copy=copy, errors=errors, **kwargs
  File "C:\ProgramData\Anaconda3\lib\site-packages\pandas\core\internals\managers.py", line 581, in astype
    return self.apply("astype", dtype=dtype, **kwargs)
  File "C:\ProgramData\Anaconda3\lib\site-packages\pandas\core\internals\managers.py", line 438, in apply
    applied = getattr(b, f)(**kwargs)
  File "C:\ProgramData\Anaconda3\lib\site-packages\pandas\core\internals\blocks.py", line 559, in astype
    return self._astype(dtype, copy=copy, errors=errors, values=values, **kwargs)
  File "C:\ProgramData\Anaconda3\lib\site-packages\pandas\core\internals\blocks.py", line 643, in _astype
    values = astype_nansafe(vals1d, dtype, copy=True, **kwargs)
  File "C:\ProgramData\Anaconda3\lib\site-packages\pandas\core\dtypes\cast.py", line 707, in astype_nansafe
    return lib.astype_intsafe(arr.ravel(), dtype).reshape(arr.shape)
  File "pandas\_libs\lib.pyx", line 547, in pandas._libs.lib.astype_intsafe
ValueError: setting an array element with a sequence.
