ERROR:root:Exception occured
Traceback (most recent call last):
  File "C:\ProgramData\Anaconda3\lib\site-packages\pandas\core\indexes\base.py", line 4730, in get_value
    return self._engine.get_value(s, k, tz=getattr(series.dtype, "tz", None))
  File "pandas\_libs\index.pyx", line 80, in pandas._libs.index.IndexEngine.get_value
  File "pandas\_libs\index.pyx", line 88, in pandas._libs.index.IndexEngine.get_value
  File "pandas\_libs\index.pyx", line 131, in pandas._libs.index.IndexEngine.get_loc
  File "pandas\_libs\hashtable_class_helper.pxi", line 992, in pandas._libs.hashtable.Int64HashTable.get_item
  File "pandas\_libs\hashtable_class_helper.pxi", line 998, in pandas._libs.hashtable.Int64HashTable.get_item
KeyError: 0

During handling of the above exception, another exception occurred:

Traceback (most recent call last):
  File "D:\ViteosModel2.0\379_Production_Model.py", line 5006, in <module>
    final_no_pair_table_copy['Task Business Date'] = final_no_pair_table_copy['Task Business Date'].fillna(pd.to_datetime(final_no_pair_table_copy['Task Business Date'].mode()[0]))
  File "C:\ProgramData\Anaconda3\lib\site-packages\pandas\core\series.py", line 1068, in __getitem__
    result = self.index.get_value(self, key)
  File "C:\ProgramData\Anaconda3\lib\site-packages\pandas\core\indexes\base.py", line 4736, in get_value
    return libindex.get_value_box(s, key)
  File "pandas\_libs\index.pyx", line 51, in pandas._libs.index.get_value_box
  File "pandas\_libs\index.pyx", line 44, in pandas._libs.index.get_value_at
  File "pandas\_libs\util.pxd", line 98, in pandas._libs.util.get_value_at
  File "pandas\_libs\util.pxd", line 89, in pandas._libs.util.validate_indexer
IndexError: index out of bounds
